Workbook

Sheet Raw Data
A1: Order_ID | B1: Customer_ID | C1: Order_Date | D1: Product | E1: Category | F1: Quantity | G1: Unit_Price | H1: City | I1: Payment_Method | J1: Clean_Payment | K1: Order_Status | L1: total_sales | M1: month
A2: ORD1111 | B2: CUST1114 | C2: 17-111125 | D2: Smartphone | E2: Electronics | F2: 1 | G2: 22111 | H2: Delhi | I2: Credit Card | J2: =PROPER(TRIM(I2)) -> Credit Card | K2: Completed | L2: =F2*G2 -> 22111 | M2: =IFERROR(MID(C2,4,2),"") -> 11
A3: ORD1112 | B3: CUST1136 | C3: 24-161125 | D3: Laptop | E3: Electronics | F3: 2 | G3: 68111 | H3: Mumbai | I3: Credit Card | J3: =PROPER(TRIM(I3)) -> Credit Card | K3: Pending | L3: =F3*G3 -> 136222 | M3: =IFERROR(MID(C3,4,2),"") -> 16
A4: ORD1113 | B4: CUST1116 | C4: 12-111125 | D4: Smartphone | E4: Electronics | F4: 1 | G4: 15111 | H4: Chennai | I4: UPI | J4: =PROPER(TRIM(I4)) -> Upi | K4: Cancelled | L4: =F4*G4 -> 15111 | M4: =IFERROR(MID(C4,4,2),"") -> 11
A5: ORD1114 | B5: CUST1149 | C5: 21-121125 | D5: Mouse | E5: Accessories | F5: 3 | G5: 411 | H5: Pune | I5: Cash | J5: =PROPER(TRIM(I5)) -> Cash | K5: Cancelled | L5: =F5*G5 -> 1233 | M5: =IFERROR(MID(C5,4,2),"") -> 12
A6: ORD1115 | B6: CUST1161 | C6: 25-131125 | D6: Monitor | E6: Electronics | F6: 2 | G6: 9111 | H6: Chennai | I6: Debit Card | J6: =PROPER(TRIM(I6)) -> Debit Card | K6: Cancelled | L6: =F6*G6 -> 18222 | M6: =IFERROR(MID(C6,4,2),"") -> 13
A7: ORD1116 | B7: CUST1192 | C7: 18-111125 | D7: Keyboard | E7: Accessories | F7: 3 | G7: 1211 | H7: Kolkata | I7: Credit Card | J7: =PROPER(TRIM(I7)) -> Credit Card | K7: Cancelled | L7: =F7*G7 -> 3633 | M7: =IFERROR(MID(C7,4,2),"") -> 11
A8: ORD1117 | B8: CUST1129 | C8: 15-171125 | D8: Smartwatch | E8: Wearables | F8: 4 | G8: 9111 | H8: Mumbai | I8: Net Banking | J8: =PROPER(TRIM(I8)) -> Net Banking | K8: Pending | L8: =F8*G8 -> 36444 | M8: =IFERROR(MID(C8,4,2),"") -> 17
A9: ORD1118 | B9: CUST1161 | C9: 12-111125 | D9: Smartphone | E9: Electronics | F9: 1 | G9: 22111 | H9: Pune | I9: Net Banking | J9: =PROPER(TRIM(I9)) -> Net Banking | K9: Completed | L9: =F9*G9 -> 22111 | M9: =IFERROR(MID(C9,4,2),"") -> 11
A10: ORD1119 | B10: CUST1198 | C10: 14-191125 | D10: Laptop | E10: Electronics | F10: 3 | G10: 15111 | H10: Mumbai | I10: Net Banking | J10: =PROPER(TRIM(I11)) -> Debit Card | K10: Completed | L10: =F10*G10 -> 45333 | M10: =IFERROR(MID(C10,4,2),"") -> 19
A11: ORD1111 | B11: CUST1115 | C11: 11-111125 | D11: Mouse | E11: Accessories | F11: 2 | G11: 1111 | H11: Jaipur | I11: Debit Card | J11: =PROPER(TRIM(I11)) -> Debit Card | K11: Completed | L11: =F11*G11 -> 2222 | M11: =IFERROR(MID(C11,4,2),"") -> 11
A12: ORD1111 | B12: CUST1122 | C12: 19-111125 | D12: Laptop | E12: Electronics | F12: 2 | G12: 45111 | H12: Pune | I12: Net Banking | J12: =PROPER(TRIM(I12)) -> Net Banking | K12: Cancelled | L12: =F12*G12 -> 90222 | M12: =IFERROR(MID(C12,4,2),"") -> 11
A13: ORD1112 | B13: CUST1132 | C13: 13-131125 | D13: Tablet | E13: Electronics | F13: 2 | G13: 35111 | H13: Bangalore | I13: unknown | J13: =PROPER(TRIM(I13)) -> Unknown | K13: Pending | L13: =F13*G13 -> 70222 | M13: =IFERROR(MID(C13,4,2),"") -> 13
A14: ORD1113 | B14: CUST1143 | C14: 17-111125 | D14: Laptop | E14: Electronics | F14: 1 | G14: 52111 | H14: Delhi | I14: Net Banking | J14: =PROPER(TRIM(I14)) -> Net Banking | K14: Completed | L14: =F14*G14 -> 52111 | M14: =IFERROR(MID(C14,4,2),"") -> 11
A15: ORD1114 | B15: CUST1185 | C15: 19-121125 | D15: Mouse | E15: Accessories | F15: 4 | G15: 711 | H15: Chennai | I15: Debit Card | J15: =PROPER(TRIM(I15)) -> Debit Card | K15: Pending | L15: =F15*G15 -> 2844 | M15: =IFERROR(MID(C15,4,2),"") -> 12
A16: ORD1115 | B16: CUST1125 | C16: 19-141125 | D16: Tablet | E16: Electronics | F16: 4 | G16: 12111 | H16: Hyderabad | I16: Credit Card | J16: =PROPER(TRIM(I16)) -> Credit Card | K16: Pending | L16: =F16*G16 -> 48444 | M16: =IFERROR(MID(C16,4,2),"") -> 14
A17: ORD1116 | B17: CUST1197 | C17: 17-121125 | D17: Headphones | E17: Accessories | F17: 3 | G17: 1211 | H17: Bangalore | I17: Credit Card | J17: =PROPER(TRIM(I17)) -> Credit Card | K17: Pending | L17: =F17*G17 -> 3633 | M17: =IFERROR(MID(C17,4,2),"") -> 12
A18: ORD1117 | B18: CUST1137 | C18: 21-181125 | D18: Smartwatch | E18: Wearables | F18: 4 | G18: 6511 | H18: Chennai | I18: Net Banking | J18: =PROPER(TRIM(I18)) -> Net Banking | K18: Cancelled | L18: =F18*G18 -> 26044 | M18: =IFERROR(MID(C18,4,2),"") -> 18
A19: ORD1118 | B19: CUST1175 | C19: 26-111125 | D19: Smartwatch | E19: Wearables | F19: 2 | G19: 2511 | H19: Hyderabad | I19: Net Banking | J19: =PROPER(TRIM(I19)) -> Net Banking | K19: Cancelled | L19: =F19*G19 -> 5022 | M19: =IFERROR(MID(C19,4,2),"") -> 11
A20: ORD1119 | B20: CUST1132 | C20: 19-111125 | D20: Headphones | E20: Accessories | F20: 1 | G20: 1211 | H20: Jaipur | I20: Net Banking | J20: =PROPER(TRIM(I21)) -> Upi | K20: Completed | L20: =F20*G20 -> 1211 | M20: =IFERROR(MID(C20,4,2),"") -> 11
A21: ORD1121 | B21: CUST1141 | C21: 18-212313 | D21: Tablet | E21: Electronics | F21: 3 | G21: 18111 | H21: Delhi | I21: UPI | J21: =PROPER(TRIM(I21)) -> Upi | K21: Pending | L21: =F21*G21 -> 54333 | M21: =IFERROR(MID(C21,4,2),"") -> 21
A22: ORD1121 | B22: CUST1157 | C22: 22-131125 | D22: Smartphone | E22: Electronics | F22: 1 | G22: 31111 | H22: Pune | I22: Net Banking | J22: =PROPER(TRIM(I22)) -> Net Banking | K22: unknown | L22: =F22*G22 -> 31111 | M22: =IFERROR(MID(C22,4,2),"") -> 13
A23: ORD1122 | B23: CUST1127 | C23: 16-111125 | D23: Laptop | E23: Electronics | F23: 3 | G23: 45111 | H23: Kolkata | I23: Credit Card | J23: =PROPER(TRIM(I23)) -> Credit Card | K23: Cancelled | L23: =F23*G23 -> 135333 | M23: =IFERROR(MID(C23,4,2),"") -> 11
A24: ORD1123 | B24: CUST1199 | C24: 21-161125 | D24: Mouse | E24: Accessories | F24: 4 | G24: 711 | H24: Mumbai | I24: unknown | J24: =PROPER(TRIM(I24)) -> Unknown | K24: Completed | L24: =F24*G24 -> 2844 | M24: =IFERROR(MID(C24,4,2),"") -> 16
A25: ORD1124 | B25: CUST1117 | C25: 19-181125 | D25: Smartwatch | E25: Wearables | F25: 4 | G25: 4111 | H25: Jaipur | I25: Debit Card | J25: =PROPER(TRIM(I25)) -> Debit Card | K25: Pending | L25: =F25*G25 -> 16444 | M25: =IFERROR(MID(C25,4,2),"") -> 18
A26: ORD1125 | B26: CUST1123 | C26: 25-131125 | D26: Laptop | E26: Electronics | F26: 3 | G26: 52111 | H26: Chennai | I26: UPI | J26: =PROPER(TRIM(I26)) -> Upi | K26: Completed | L26: =F26*G26 -> 156333 | M26: =IFERROR(MID(C26,4,2),"") -> 13
A27: ORD1126 | B27: CUST1126 | C27: 24-141125 | D27: Monitor | E27: Electronics | F27: 4 | G27: 22111 | H27: Hyderabad | I27: Debit Card | J27: =PROPER(TRIM(I27)) -> Debit Card | K27: Pending | L27: =F27*G27 -> 88444 | M27: =IFERROR(MID(C27,4,2),"") -> 14
A28: ORD1127 | B28: CUST1166 | C28: 25-111125 | D28: Keyboard | E28: Accessories | F28: 2 | G28: 1211 | H28: Chennai | I28: Net Banking | J28: =PROPER(TRIM(I28)) -> Net Banking | K28: Pending | L28: =F28*G28 -> 2422 | M28: =IFERROR(MID(C28,4,2),"") -> 11
A29: ORD1128 | B29: CUST1178 | C29: 12-181125 | D29: Laptop | E29: Electronics | F29: 1 | G29: 61111 | H29: Delhi | I29: Cash | J29: =PROPER(TRIM(I29)) -> Cash | K29: Cancelled | L29: =F29*G29 -> 61111 | M29: =IFERROR(MID(C29,4,2),"") -> 18
A30: ORD1129 | B30: CUST1186 | C30: 15-121125 | D30: Keyboard | E30: Accessories | F30: 0 | G30: 1811 | H30: Kolkata | I30: Net Banking | J30: =PROPER(TRIM(I31)) -> Credit Card | K30: Pending | L30: =F30*G30 -> 0 | M30: =IFERROR(MID(C30,4,2),"") -> 12
A31: ORD1131 | B31: CUST1186 | C31: 14-181125 | D31: Smartphone | E31: Electronics | F31: 3 | G31: 42111 | H31: Chennai | I31: Credit Card | J31: =PROPER(TRIM(I31)) -> Credit Card | K31: Cancelled | L31: =F31*G31 -> 126333 | M31: =IFERROR(MID(C31,4,2),"") -> 18
A32: ORD1131 | B32: CUST1187 | C32: 15-181125 | D32: Mouse | E32: Accessories | F32: 4 | G32: 711 | H32: Bangalore | I32: Net Banking | J32: =PROPER(TRIM(I32)) -> Net Banking | K32: Pending | L32: =F32*G32 -> 2844 | M32: =IFERROR(MID(C32,4,2),"") -> 18
A33: ORD1132 | B33: CUST1114 | C33: 17-131125 | D33: Headphones | E33: Accessories | F33: 1 | G33: 1211 | H33: Jaipur | I33: Credit Card | J33: =PROPER(TRIM(I33)) -> Credit Card | K33: Pending | L33: =F33*G33 -> 1211 | M33: =IFERROR(MID(C33,4,2),"") -> 13
A34: ORD1133 | B34: CUST1111 | C34: 24-121125 | D34: Smartphone | E34: Electronics | F34: 4 | G34: 22111 | H34: Chennai | I34: Credit Card | J34: =PROPER(TRIM(I34)) -> Credit Card | K34: Completed | L34: =F34*G34 -> 88444 | M34: =IFERROR(MID(C34,4,2),"") -> 12
A35: ORD1134 | B35: CUST1158 | C35: 18-111125 | D35: Smartwatch | E35: Wearables | F35: 1 | G35: 9111 | H35: Mumbai | I35: Cash | J35: =PROPER(TRIM(I35)) -> Cash | K35: Pending | L35: =F35*G35 -> 9111 | M35: =IFERROR(MID(C35,4,2),"") -> 11
A36: ORD1135 | B36: CUST1143 | C36: 21-151125 | D36: Mouse | E36: Accessories | F36: 2 | G36: 711 | H36: Kolkata | I36: Net Banking | J36: =PROPER(TRIM(I36)) -> Net Banking | K36: Completed | L36: =F36*G36 -> 1422 | M36: =IFERROR(MID(C36,4,2),"") -> 15
A37: ORD1136 | B37: CUST1171 | C37: 19-161125 | D37: Headphones | E37: Accessories | F37: 2 | G37: 1811 | H37: Hyderabad | I37: Cash | J37: =PROPER(TRIM(I37)) -> Cash | K37: Completed | L37: =F37*G37 -> 3622 | M37: =IFERROR(MID(C37,4,2),"") -> 16
A38: ORD1137 | B38: CUST1169 | C38: 13-181125 | D38: Keyboard | E38: Accessories | F38: 4 | G38: 1211 | H38: Bangalore | I38: Cash | J38: =PROPER(TRIM(I38)) -> Cash | K38: Completed | L38: =F38*G38 -> 4844 | M38: =IFERROR(MID(C38,4,2),"") -> 18
A39: ORD1138 | B39: CUST1181 | C39: 17-131125 | D39: Mouse | E39: Accessories | F39: 4 | G39: 1111 | H39: Jaipur | I39: Cash | J39: =PROPER(TRIM(I39)) -> Cash | K39: Cancelled | L39: =F39*G39 -> 4444 | M39: =IFERROR(MID(C39,4,2),"") -> 13
A40: ORD1139 | B40: CUST1159 | C40: 19-141125 | D40: Laptop | E40: Electronics | F40: 1 | G40: 68111 | H40: Kolkata | I40: Debit Card | J40: =PROPER(TRIM(I41)) -> Upi | K40: Pending | L40: =F40*G40 -> 68111 | M40: =IFERROR(MID(C40,4,2),"") -> 14
...

Sheet cleaning summary
A1: Cleaning Task | B1: Action Taken
A2: Missing Values | B2: Blank City values changed to Unknown
A3: Duplicate Records | B3: Duplicate rows removed
A4: City | B4: City names standardized
A5: Product | B5: Product names standardized
A6: Payment Method | B6: Payment methods standardized
A7: Quantity | B7: Invalid values corrected
A8: Unit Price | B8: Price formatting corrected
A9: Order Date | B9: ate format standardized
A10: Total Sales | B10: Quantity × Unit Price calculated

Sheet Learning Guide
A1: Step | B1: What to learn
A2: 1. Inspect the dataset | B2: Understand rows, columns, fields and data types
A3: 2. Find missing values | B3: Use filters and blanks to identify missing data
A4: 3. Find duplicate records | B4: Use Remove Duplicates
A5: 4. Standardize inconsistent text | B5: Use TRIM, Find/Replace and consistent labels
A6: 5. Fix date format | B6: Convert dates into one format
A7: 6. Fix numeric values/data types | B7: Convert Quantity and Unit_Price to numbers
A8: 7. Check incorrect values | B8: Use sorting/filtering to spot impossible values
A9: 8. Create a Total_Sales column | B9: Quantity × Unit_Price
A10: 9. Create a cleaning summary | B10: Document what you changed
A11: 10. Save the cleaned dataset | B11: Keep raw and cleaned versions separate

Sheet EDA analysis
A1: Cell | B1: Type
A2: A1 | B2: EXPLORATORY DATA ANALYSIS
A3: A3 | B3: Metric
A4: B3 | B4: Value
A5: A4 | B5: Total Orders | C5: =COUNTA('Raw Data'!A2:A301) -> 300
A6: A5 | B6: Total Sales | C6: =_xlfn.AGGREGATE(9,6,'Raw Data'!L2:L301) -> 11366007
A7: A6 | B7: Average Sales per Order | C7: =_xlfn.AGGREGATE(1,6,'Raw Data'!L2:L301) -> 38013.401
A8: A7 | B8: Average Quantity | C8: =AVERAGE('Raw Data'!F2:F301) -> 2.4455782
A9: A8 | B9: Highest Sale | C9: =_xlfn.AGGREGATE(4,6,'Raw Data'!L2:L301) -> 272444
A10: A9 | B10: Lowest Sale | C10: =_xlfn.AGGREGATE(5,6,'Raw Data'!L2:L301) -> 0
A11: A10 | B11: Median Sale | C11: =_xlfn.AGGREGATE(12,6,'Raw Data'!L2:L301) -> 14044
A13: Category Sales Analysis
A14: Cell | B14: Type
A15: A15 | B15: Category
A16: B15 | B16: Total Sales
A17: B16 | B17: Electronics | C17: {=SUMPRODUCT((TRIM('Raw Data'!E2:E301)="Electronics")*IFERROR('Raw Data'!L2:L301,0))} -> 10303520
A18: B17 | B18: Wearables | C18: {=SUMPRODUCT((TRIM('Raw Data'!E2:E301)="Wearables")*IFERROR('Raw Data'!L2:L301,0))} -> 642387
A19: B18 | B19: Accessories | C19: {=SUMPRODUCT((TRIM('Raw Data'!E2:E301)="Accessories")*IFERROR('Raw Data'!L2:L301,0))} -> 420100
A20: A19
A22: Cell | B22: Enter
A23: A21 | B23: Product Sales Analysis
A24: A23 | B24: Product
A25: B23 | B25: Total Sales
A26: A24 | B26: Smartphone | C26: =SUMIF('Raw Data'!D2:D301,"Smartphone",'Raw Data'!L2:L301) -> 2744389
A27: A25 | B27: Laptop | C27: =SUMIF('Raw Data'!D2:D301,"Laptop",'Raw Data'!L2:L301) -> 5156878
A28: A26 | B28: Mouse | C28: =SUMIF('Raw Data'!D2:D301,"Mouse",'Raw Data'!L2:L301) -> 95297
A29: A27 | B29: Monitor | C29: =SUMIF('Raw Data'!D2:D301,"Monitor",'Raw Data'!L2:L301) -> 1062104
A30: A28 | B30: Keyboard | C30: =SUMIF('Raw Data'!D2:D301,"Keyboard",'Raw Data'!L2:L301) -> 128812
A31: A29 | B31: Smartwatch | C31: =SUMIF('Raw Data'!D2:D301,"Smartwatch",'Raw Data'!L2:L301) -> 632343
A32: A30 | B32: Tablet | C32: =SUMIF('Raw Data'!D2:D301,"Tablet",'Raw Data'!L2:L301) -> 1313215
A33: A31 | B33: Headphones | C33: {=SUMPRODUCT(--('Raw Data'!D2:D301="Headphones"),IFERROR('Raw Data'!L2:L301,0))} -> 187636
A35: Cell | B35: Enter
A36: A34 | B36: Order Status Analysis
A37: A36 | B37: Status
A38: B36 | B38: Number of Orders
A39: A37 | B39: Completed | C39: =COUNTIF('Raw Data'!K2:K301,"Completed") -> 91
A40: A38 | B40: Pending | C40: =COUNTIF('Raw Data'!K2:K301,"Pending") -> 101
A41: A39 | B41: Cancelled | C41: =COUNTIF('Raw Data'!K2:K301,"Cancelled") -> 103
A42: A40 | B42: Unknown | C42: =COUNTIF('Raw Data'!K2:K301,"unknown") -> 5
B43: total | C43: 300
...
