Workbook
Name Slicer_Category: #N/A
Name Slicer_city_clean: #N/A
Name Slicer_Order_Status: #N/A

Sheet Raw Data
A1: Order_ID | B1: Customer_ID | C1: Order_Date | D1: Product | E1: Category | F1: Quantity | G1: Unit_Price | H1: City | I1: Payment_Method | J1: Clean_Payment | K1: Order_Status | L1: total_sales | M1: month
A2: ORD1111 | B2: CUST1114 | C2: 17-111125 | D2: Smartphone | E2: Electronics | F2: 1 | G2: 22111 | H2: Delhi | I2: Credit Card | J2: =PROPER(TRIM(I2)) -> Credit Card | K2: Completed | L2: =F2*G2 -> 22111 | M2: =IFERROR(MID(C2,4,2),"") -> 11
A3: ORD1112 | B3: CUST1136 | C3: 24-161125 | D3: Laptop | E3: Electronics | F3: 2 | G3: 68111 | H3: Mumbai | I3: Credit Card | J3: =PROPER(TRIM(I3)) -> Credit Card | K3: Pending | L3: =F3*G3 -> 136222 | M3: =IFERROR(MID(C3,4,2),"") -> 16
A4: ORD1113 | B4: CUST1116 | C4: 12-111125 | D4: Smartphone | E4: Electronics | F4: 1 | G4: 15111 | H4: Chennai | I4: UPI | J4: =PROPER(TRIM(I4)) -> Upi | K4: Cancelled | L4: =F4*G4 -> 15111 | M4: =IFERROR(MID(C4,4,2),"") -> 11
A5: ORD1114 | B5: CUST1149 | C5: 21-121125 | D5: Mouse | E5: Accessories | F5: 3 | G5: 411 | H5: Pune | I5: Cash | J5: =PROPER(TRIM(I5)) -> Cash | K5: Cancelled | L5: =F5*G5 -> 1233 | M5: =IFERROR(MID(C5,4,2),"") -> 12
A6: ORD1115 | B6: CUST1161 | C6: 25-131125 | D6: Monitor | E6: Electronics | F6: 2 | G6: 9111 | H6: Chennai | I6: Debit Card | J6: =PROPER(TRIM(I6)) -> Debit Card | K6: Cancelled | L6: =F6*G6 -> 18222 | M6: =IFERROR(MID(C6,4,2),"") -> 13
A7: ORD1116 | B7: CUST1192 | C7: 18-111125 | D7: Keyboard | E7: Accessories | F7: 3 | G7: 1211 | H7: Kolkata | I7: Credit Card | J7: =PROPER(TRIM(I7)) -> Credit Card | K7: Cancelled | L7: =F7*G7 -> 3633 | M7: =IFERROR(MID(C7,4,2),"") -> 11
A8: ORD1117 | B8: CUST1129 | C8: 15-171125 | D8: Smartwatch | E8: Wearables | F8: 4 | G8: 9111 | H8: Mumbai | I8: Net Banking | J8: =PROPER(TRIM(I8)) -> Net Banking | K8: Pending | L8: =F8*G8 -> 36444 | M8: =IFERROR(MID(C8,4,2),"") -> 17
A9: ORD1118 | B9: CUST1161 | C9: 12-111125 | D9: Smartphone | E9: Electronics | F9: 1 | G9: 22111 | H9: Pune | I9: Net Banking | J9: =PROPER(TRIM(I9)) -> Net Banking | K9: Completed | L9: =F9*G9 -> 22111 | M9: =IFERROR(MID(C9,4,2),"") -> 11
A10: ORD1119 | B10: CUST1198 | C10: 14-191125 | D10: Laptop | E10: Electronics | F10: 3 | G10: 15111 | H10: Mumbai | I10: Net Banking | J10: =PROPER(TRIM(I11)) -> Debit Card | K10: Completed | L10: =F10*G10 -> 45333 | M10: =IFERROR(MID(C10,4,2),"") -> 19
A11: ORD1111 | B11: CUST1115 | C11: 11-111125 | D11: Mouse | E11: Accessories | F11: 2 | G11: 1111 | H11: Jaipur | I11: Debit Card | J11: =PROPER(TRIM(I11)) -> Debit Card | K11: Completed | L11: =F11*G11 -> 2222 | M11: =IFERROR(MID(C11,4,2),"") -> 11
A12: ORD1111 | B12: CUST1122 | C12: 19-111125 | D12: Laptop | E12: Electronics | F12: 2 | G12: 45111 | H12: Pune | I12: Net Banking | J12: =PROPER(TRIM(I12)) -> Net Banking | K12: Cancelled | L12: =F12*G12 -> 90222 | M12: =IFERROR(MID(C12,4,2),"") -> 11
A13: ORD1112 | B13: CUST1132 | C13: 13-131125 | D13: Tablet | E13: Electronics | F13: 2 | G13: 35111 | H13: Bangalore | I13: unknown | J13: =PROPER(TRIM(I13)) -> Unknown | K13: Pending | L13: =F13*G13 -> 70222 | M13: =IFERROR(MID(C13,4,2),"") -> 13
A14: ORD1113 | B14: CUST1143 | C14: 17-111125 | D14: Laptop | E14: Electronics | F14: 1 | G14: 52111 | H14: Delhi | I14: Net Banking | J14: =PROPER(TRIM(I14)) -> Net Banking | K14: Completed | L14: =F14*G14 -> 52111 | M14: =IFERROR(MID(C14,4,2),"") -> 11
A15: ORD1114 | B15: CUST1185 | C15: 19-121125 | D15: Mouse | E15: Accessories | F15: 4 | G15: 711 | H15: Chennai | I15: Debit Card | J15: =PROPER(TRIM(I15)) -> Debit Card | K15: Pending | L15: =F15*G15 -> 2844 | M15: =IFERROR(MID(C15,4,2),"") -> 12
A16: ORD1115 | B16: CUST1125 | C16: 19-141125 | D16: Tablet | E16: Electronics | F16: 4 | G16: 12111 | H16: Hyderabad | I16: Credit Card | J16: =PROPER(TRIM(I16)) -> Credit Card | K16: Pending | L16: =F16*G16 -> 48444 | M16: =IFERROR(MID(C16,4,2),"") -> 14
A17: ORD1116 | B17: CUST1197 | C17: 17-121125 | D17: Headphones | E17: Accessories | F17: 3 | G17: 1211 | H17: Bangalore | I17: Credit Card | J17: =PROPER(TRIM(I17)) -> Credit Card | K17: Pending | L17: =F17*G17 -> 3633 | M17: =IFERROR(MID(C17,4,2),"") -> 12
A18: ORD1117 | B18: CUST1137 | C18: 21-181125 | D18: Smartwatch | E18: Wearables | F18: 4 | G18: 6511 | H18: Chennai | I18: Net Banking | J18: =PROPER(TRIM(I18)) -> Net Banking | K18: Cancelled | L18: =F18*G18 -> 26044 | M18: =IFERROR(MID(C18,4,2),"") -> 18
A19: ORD1118 | B19: CUST1175 | C19: 26-111125 | D19: Smartwatch | E19: Wearables | F19: 2 | G19: 2511 | H19: Hyderabad | I19: Net Banking | J19: =PROPER(TRIM(I19)) -> Net Banking | K19: Cancelled | L19: =F19*G19 -> 5022 | M19: =IFERROR(MID(C19,4,2),"") -> 11
A20: ORD1119 | B20: CUST1132 | C20: 19-111125 | D20: Headphones | E20: Accessories | F20: 1 | G20: 1211 | H20: Jaipur | I20: Net Banking | J20: =PROPER(TRIM(I21)) -> Upi | K20: Completed | L20: =F20*G20 -> 1211 | M20: =IFERROR(MID(C20,4,2),"") -> 11
A21: ORD1121 | B21: CUST1141 | C21: 18-212313 | D21: Tablet | E21: Electronics | F21: 3 | G21: 18111 | H21: Delhi | I21: UPI | J21: =PROPER(TRIM(I21)) -> Upi | K21: Pending | L21: =F21*G21 -> 54333 | M21: =IFERROR(MID(C21,4,2),"") -> 21
A22: ORD1121 | B22: CUST1157 | C22: 22-131125 | D22: Smartphone | E22: Electronics | F22: 1 | G22: 31111 | H22: Pune | I22: Net Banking | J22: =PROPER(TRIM(I22)) -> Net Banking | K22: unknown | L22: =F22*G22 -> 31111 | M22: =IFERROR(MID(C22,4,2),"") -> 13
A23: ORD1122 | B23: CUST1127 | C23: 16-111125 | D23: Laptop | E23: Electronics | F23: 3 | G23: 45111 | H23: Kolkata | I23: Credit Card | J23: =PROPER(TRIM(I23)) -> Credit Card | K23: Cancelled | L23: =F23*G23 -> 135333 | M23: =IFERROR(MID(C23,4,2),"") -> 11
A24: ORD1123 | B24: CUST1199 | C24: 21-161125 | D24: Mouse | E24: Accessories | F24: 4 | G24: 711 | H24: Mumbai | I24: unknown | J24: =PROPER(TRIM(I24)) -> Unknown | K24: Completed | L24: =F24*G24 -> 2844 | M24: =IFERROR(MID(C24,4,2),"") -> 16
A25: ORD1124 | B25: CUST1117 | C25: 19-181125 | D25: Smartwatch | E25: Wearables | F25: 4 | G25: 4111 | H25: Jaipur | I25: Debit Card | J25: =PROPER(TRIM(I25)) -> Debit Card | K25: Pending | L25: =F25*G25 -> 16444 | M25: =IFERROR(MID(C25,4,2),"") -> 18
A26: ORD1125 | B26: CUST1123 | C26: 25-131125 | D26: Laptop | E26: Electronics | F26: 3 | G26: 52111 | H26: Chennai | I26: UPI | J26: =PROPER(TRIM(I26)) -> Upi | K26: Completed | L26: =F26*G26 -> 156333 | M26: =IFERROR(MID(C26,4,2),"") -> 13
A27: ORD1126 | B27: CUST1126 | C27: 24-141125 | D27: Monitor | E27: Electronics | F27: 4 | G27: 22111 | H27: Hyderabad | I27: Debit Card | J27: =PROPER(TRIM(I27)) -> Debit Card | K27: Pending | L27: =F27*G27 -> 88444 | M27: =IFERROR(MID(C27,4,2),"") -> 14
A28: ORD1127 | B28: CUST1166 | C28: 25-111125 | D28: Keyboard | E28: Accessories | F28: 2 | G28: 1211 | H28: Chennai | I28: Net Banking | J28: =PROPER(TRIM(I28)) -> Net Banking | K28: Pending | L28: =F28*G28 -> 2422 | M28: =IFERROR(MID(C28,4,2),"") -> 11
A29: ORD1128 | B29: CUST1178 | C29: 12-181125 | D29: Laptop | E29: Electronics | F29: 1 | G29: 61111 | H29: Delhi | I29: Cash | J29: =PROPER(TRIM(I29)) -> Cash | K29: Cancelled | L29: =F29*G29 -> 61111 | M29: =IFERROR(MID(C29,4,2),"") -> 18
A30: ORD1129 | B30: CUST1186 | C30: 15-121125 | D30: Keyboard | E30: Accessories | F30: 0 | G30: 1811 | H30: Kolkata | I30: Net Banking | J30: =PROPER(TRIM(I31)) -> Credit Card | K30: Pending | L30: =F30*G30 -> 0 | M30: =IFERROR(MID(C30,4,2),"") -> 12
A31: ORD1131 | B31: CUST1186 | C31: 14-181125 | D31: Smartphone | E31: Electronics | F31: 3 | G31: 42111 | H31: Chennai | I31: Credit Card | J31: =PROPER(TRIM(I31)) -> Credit Card | K31: Cancelled | L31: =F31*G31 -> 126333 | M31: =IFERROR(MID(C31,4,2),"") -> 18
A32: ORD1131 | B32: CUST1187 | C32: 15-181125 | D32: Mouse | E32: Accessories | F32: 4 | G32: 711 | H32: Bangalore | I32: Net Banking | J32: =PROPER(TRIM(I32)) -> Net Banking | K32: Pending | L32: =F32*G32 -> 2844 | M32: =IFERROR(MID(C32,4,2),"") -> 18
A33: ORD1132 | B33: CUST1114 | C33: 17-131125 | D33: Headphones | E33: Accessories | F33: 1 | G33: 1211 | H33: Jaipur | I33: Credit Card | J33: =PROPER(TRIM(I33)) -> Credit Card | K33: Pending | L33: =F33*G33 -> 1211 | M33: =IFERROR(MID(C33,4,2),"") -> 13
A34: ORD1133 | B34: CUST1111 | C34: 24-121125 | D34: Smartphone | E34: Electronics | F34: 4 | G34: 22111 | H34: Chennai | I34: Credit Card | J34: =PROPER(TRIM(I34)) -> Credit Card | K34: Completed | L34: =F34*G34 -> 88444 | M34: =IFERROR(MID(C34,4,2),"") -> 12
A35: ORD1134 | B35: CUST1158 | C35: 18-111125 | D35: Smartwatch | E35: Wearables | F35: 1 | G35: 9111 | H35: Mumbai | I35: Cash | J35: =PROPER(TRIM(I35)) -> Cash | K35: Pending | L35: =F35*G35 -> 9111 | M35: =IFERROR(MID(C35,4,2),"") -> 11
A36: ORD1135 | B36: CUST1143 | C36: 21-151125 | D36: Mouse | E36: Accessories | F36: 2 | G36: 711 | H36: Kolkata | I36: Net Banking | J36: =PROPER(TRIM(I36)) -> Net Banking | K36: Completed | L36: =F36*G36 -> 1422 | M36: =IFERROR(MID(C36,4,2),"") -> 15
A37: ORD1136 | B37: CUST1171 | C37: 19-161125 | D37: Headphones | E37: Accessories | F37: 2 | G37: 1811 | H37: Hyderabad | I37: Cash | J37: =PROPER(TRIM(I37)) -> Cash | K37: Completed | L37: =F37*G37 -> 3622 | M37: =IFERROR(MID(C37,4,2),"") -> 16
A38: ORD1137 | B38: CUST1169 | C38: 13-181125 | D38: Keyboard | E38: Accessories | F38: 4 | G38: 1211 | H38: Bangalore | I38: Cash | J38: =PROPER(TRIM(I38)) -> Cash | K38: Completed | L38: =F38*G38 -> 4844 | M38: =IFERROR(MID(C38,4,2),"") -> 18
A39: ORD1138 | B39: CUST1181 | C39: 17-131125 | D39: Mouse | E39: Accessories | F39: 4 | G39: 1111 | H39: Jaipur | I39: Cash | J39: =PROPER(TRIM(I39)) -> Cash | K39: Cancelled | L39: =F39*G39 -> 4444 | M39: =IFERROR(MID(C39,4,2),"") -> 13
A40: ORD1139 | B40: CUST1159 | C40: 19-141125 | D40: Laptop | E40: Electronics | F40: 1 | G40: 68111 | H40: Kolkata | I40: Debit Card | J40: =PROPER(TRIM(I41)) -> Upi | K40: Pending | L40: =F40*G40 -> 68111 | M40: =IFERROR(MID(C40,4,2),"") -> 14
...

Sheet cleaning summary
A1: Cleaning Task | B1: Action Taken
A2: Missing Values | B2: Blank City values changed to Unknown
A3: Duplicate Records | B3: Duplicate rows removed
A4: City | B4: City names standardized
A5: Product | B5: Product names standardized
A6: Payment Method | B6: Payment methods standardized
A7: Quantity | B7: Invalid values corrected
A8: Unit Price | B8: Price formatting corrected
A9: Order Date | B9: ate format standardized
A10: Total Sales | B10: Quantity × Unit Price calculated

Sheet Learning Guide
A1: Step | B1: What to learn
A2: 1. Inspect the dataset | B2: Understand rows, columns, fields and data types
A3: 2. Find missing values | B3: Use filters and blanks to identify missing data
A4: 3. Find duplicate records | B4: Use Remove Duplicates
A5: 4. Standardize inconsistent text | B5: Use TRIM, Find/Replace and consistent labels
A6: 5. Fix date format | B6: Convert dates into one format
A7: 6. Fix numeric values/data types | B7: Convert Quantity and Unit_Price to numbers
A8: 7. Check incorrect values | B8: Use sorting/filtering to spot impossible values
A9: 8. Create a Total_Sales column | B9: Quantity × Unit_Price
A10: 9. Create a cleaning summary | B10: Document what you changed
A11: 10. Save the cleaned dataset | B11: Keep raw and cleaned versions separate

Sheet EDA analysis
A1: Cell | B1: Type
A2: A1 | B2: EXPLORATORY DATA ANALYSIS
A3: A3 | B3: Metric
A4: B3 | B4: Value
A5: A4 | B5: Total Orders | C5: =COUNTA('Raw Data'!A2:A301) -> 300
A6: A5 | B6: Total Sales | C6: =_xlfn.AGGREGATE(9,6,'Raw Data'!L2:L301) -> 11366007
A7: A6 | B7: Average Sales per Order | C7: =_xlfn.AGGREGATE(1,6,'Raw Data'!L2:L301) -> 38013.401
A8: A7 | B8: Average Quantity | C8: =AVERAGE('Raw Data'!F2:F301) -> 2.4455782
A9: A8 | B9: Highest Sale | C9: =_xlfn.AGGREGATE(4,6,'Raw Data'!L2:L301) -> 272444
A10: A9 | B10: Lowest Sale | C10: =_xlfn.AGGREGATE(5,6,'Raw Data'!L2:L301) -> 0
A11: A10 | B11: Median Sale | C11: =_xlfn.AGGREGATE(12,6,'Raw Data'!L2:L301) -> 14044
A13: Category Sales Analysis
A14: Cell | B14: Type
A15: A15 | B15: Category
A16: B15 | B16: Total Sales
A17: B16 | B17: Electronics | C17: {=SUMPRODUCT((TRIM('Raw Data'!E2:E301)="Electronics")*IFERROR('Raw Data'!L2:L301,0))} -> 10303520
A18: B17 | B18: Wearables | C18: {=SUMPRODUCT((TRIM('Raw Data'!E2:E301)="Wearables")*IFERROR('Raw Data'!L2:L301,0))} -> 642387
A19: B18 | B19: Accessories | C19: {=SUMPRODUCT((TRIM('Raw Data'!E2:E301)="Accessories")*IFERROR('Raw Data'!L2:L301,0))} -> 420100
A20: A19
A22: Cell | B22: Enter
A23: A21 | B23: Product Sales Analysis
A24: A23 | B24: Product
A25: B23 | B25: Total Sales
A26: A24 | B26: Smartphone | C26: =SUMIF('Raw Data'!D2:D301,"Smartphone",'Raw Data'!L2:L301) -> 2744389
A27: A25 | B27: Laptop | C27: =SUMIF('Raw Data'!D2:D301,"Laptop",'Raw Data'!L2:L301) -> 5156878
A28: A26 | B28: Mouse | C28: =SUMIF('Raw Data'!D2:D301,"Mouse",'Raw Data'!L2:L301) -> 95297
A29: A27 | B29: Monitor | C29: =SUMIF('Raw Data'!D2:D301,"Monitor",'Raw Data'!L2:L301) -> 1062104
A30: A28 | B30: Keyboard | C30: =SUMIF('Raw Data'!D2:D301,"Keyboard",'Raw Data'!L2:L301) -> 128812
A31: A29 | B31: Smartwatch | C31: =SUMIF('Raw Data'!D2:D301,"Smartwatch",'Raw Data'!L2:L301) -> 632343
A32: A30 | B32: Tablet | C32: =SUMIF('Raw Data'!D2:D301,"Tablet",'Raw Data'!L2:L301) -> 1313215
A33: A31 | B33: Headphones | C33: {=SUMPRODUCT(--('Raw Data'!D2:D301="Headphones"),IFERROR('Raw Data'!L2:L301,0))} -> 187636
A35: Cell | B35: Enter
A36: A34 | B36: Order Status Analysis
A37: A36 | B37: Status
A38: B36 | B38: Number of Orders
A39: A37 | B39: Completed | C39: =COUNTIF('Raw Data'!K2:K301,"Completed") -> 91
A40: A38 | B40: Pending | C40: =COUNTIF('Raw Data'!K2:K301,"Pending") -> 101
A41: A39 | B41: Cancelled | C41: =COUNTIF('Raw Data'!K2:K301,"Cancelled") -> 103
A42: A40 | B42: Unknown | C42: =COUNTIF('Raw Data'!K2:K301,"unknown") -> 5
B43: total | C43: 300
...

Sheet calc
A3: Sum of sales | B3: Count of Order_ID | C3: Average of sales2
A4: 11366007 | B4: 300 | C4: 37886.69

Sheet dashboard
B1: sales dashboard
B2: total_sales | D2: total_orders | F2: average_order_value
B3: =GETPIVOTDATA("Sum of sales",calc!$A$3) -> 11366007 | D3: =GETPIVOTDATA("Count of Order_ID",calc!$A$3) -> 300 | F3: =B3/D3 -> 37886.69
AC40: 9

Sheet Sheet1
A3: Row Labels | B3: Sum of sales
A4: Accessories | B4: 420100
A5: Electronics | B5: 10303520
A6: Wearables | B6: 642387
A7: Grand Total | B7: 11366007

Sheet Sheet2
A3: Row Labels | B3: Sum of sales
A4: Laptop | B4: 45333
A5: Headphones | B5: 187636
A6: Keyboard | B6: 128812
A7: Laptop | B7: 5156878
A8: Monitor | B8: 1062104
A9: Mouse | B9: 95297
A10: Smartphone | B10: 2744389
A11: Smartwatch | B11: 632343
A12: Tablet | B12: 1313215
A13: Grand Total | B13: 11366007

Sheet Sheet3
A3: Row Labels | B3: Sum of sales
A4: Jaipur | B4: 27688
A5: Mumbai | B5: 161421
A6: Bangalore | B6: 1064570
A7: Chennai | B7: 2380454
A8: Delhi | B8: 1015214
A9: Hyderabad | B9: 1591867
A10: Jaipur | B10: 566993
A11: Kolkata | B11: 1329700
A12: Mumbai | B12: 1931755
A13: Pune | B13: 1025391
A14: unknown | B14: 270954
A15: Grand Total | B15: 11366007

Sheet Sheet4
A3: Row Labels | B3: Count of Order_ID
A4: Cancelled | B4: 103
A5: Completed | B5: 91
A6: Pending | B6: 101
A7: unknown | B7: 5
A8: Grand Total | B8: 300

Sheet Sheet5
A3: Row Labels | B3: Count of Order_ID
A4: Cash | B4: 51
A5: Credit Card | B5: 58
A6: Debit Card | B6: 65
A7: Net Banking | B7: 63
A8: unknown | B8: 6
A9: UPI | B9: 55
A10: UPI | B10: 2
A11: Grand Total | B11: 300

Sheet Sheet6
A3: Row Labels | B3: Sum of sales
A4: 11 | B4: 930760
A5: 12 | B5: 306996
A6: 13 | B6: 1000073
A7: 14 | B7: 738039
A8: 15 | B8: 929350
A9: 16 | B9: 911884
A10: 17 | B10: 740350
A11: 18 | B11: 619206
A12: 19 | B12: 946594
A13: 21 | B13: 378050
A14: 22 | B14: 551575
A15: 23 | B15: 401630
... A22: 31 | B22: 315675
A23: Grand Total | B23: 11366007

Sheet data
A1: Order_ID | B1: Customer_ID | C1: Order_Date | D1: Product | E1: Category | F1: Quantity | G1: Unit_Price | H1: City | I1: Payment_Method | J1: Order_Status | K1: city_clean | L1: Column1 | M1: sales | N1: day
A2: ORD1111 | B2: CUST1114 | C2: 17-111125 | D2: Smartphone | E2: Electronics | F2: 1 | G2: 22111 | H2: Delhi | I2: Credit Card | J2: Completed | K2: =PROPER(TRIM(H2)) -> Delhi | L2: payment_mentod | M2: =IFERROR(F2*G2,0) -> 22111 | N2: =IFERROR(VALUE(LEFT(C2,2)),"") -> 17
A3: ORD1112 | B3: CUST1136 | C3: 24-161125 | D3: Laptop | E3: Electronics | F3: 2 | G3: 68111 | H3: Mumbai | I3: Credit Card | J3: Pending | K3: =PROPER(TRIM(H3)) -> Mumbai | L3: =IF(UPPER(TRIM(I2))="UPI","UPI",PROPER(TRIM(I2))) -> Credit Card | M3: =IFERROR(F3*G3,0) -> 136222 | N3: =IFERROR(VALUE(LEFT(C3,2)),"") -> 24
A4: ORD1113 | B4: CUST1116 | C4: 12-111125 | D4: Smartphone | E4: Electronics | F4: 1 | G4: 15111 | H4: Chennai | I4: UPI | J4: Cancelled | K4: =PROPER(TRIM(H4)) -> Chennai | L4: =IF(UPPER(TRIM(I3))="UPI","UPI",PROPER(TRIM(I3))) -> Credit Card | M4: =IFERROR(F4*G4,0) -> 15111 | N4: =IFERROR(VALUE(LEFT(C4,2)),"") -> 12
A5: ORD1114 | B5: CUST1149 | C5: 21-121125 | D5: Mouse | E5: Accessories | F5: 3 | G5: 411 | H5: Pune | I5: Cash | J5: Cancelled | K5: =PROPER(TRIM(H5)) -> Pune | L5: =IF(UPPER(TRIM(I4))="UPI","UPI",PROPER(TRIM(I4))) -> UPI | M5: =IFERROR(F5*G5,0) -> 1233 | N5: =IFERROR(VALUE(LEFT(C5,2)),"") -> 21
A6: ORD1115 | B6: CUST1161 | C6: 25-131125 | D6: Monitor | E6: Electronics | F6: 2 | G6: 9111 | H6: Chennai | I6: Debit Card | J6: Cancelled | K6: =PROPER(TRIM(H6)) -> Chennai | L6: =IF(UPPER(TRIM(I5))="UPI","UPI",PROPER(TRIM(I5))) -> Cash | M6: =IFERROR(F6*G6,0) -> 18222 | N6: =IFERROR(VALUE(LEFT(C6,2)),"") -> 25
A7: ORD1116 | B7: CUST1192 | C7: 18-111125 | D7: Keyboard | E7: Accessories | F7: 3 | G7: 1211 | H7: Kolkata | I7: Credit Card | J7: Cancelled | K7: =PROPER(TRIM(H7)) -> Kolkata | L7: =IF(UPPER(TRIM(I6))="UPI","UPI",PROPER(TRIM(I6))) -> Debit Card | M7: =IFERROR(F7*G7,0) -> 3633 | N7: =IFERROR(VALUE(LEFT(C7,2)),"") -> 18
A8: ORD1117 | B8: CUST1129 | C8: 15-171125 | D8: Smartwatch | E8: Wearables | F8: 4 | G8: 9111 | H8: Mumbai | I8: Net Banking | J8: Pending | K8: =PROPER(TRIM(H8)) -> Mumbai | L8: =IF(UPPER(TRIM(I7))="UPI","UPI",PROPER(TRIM(I7))) -> Credit Card | M8: =IFERROR(F8*G8,0) -> 36444 | N8: =IFERROR(VALUE(LEFT(C8,2)),"") -> 15
A9: ORD1118 | B9: CUST1161 | C9: 12-111125 | D9: Smartphone | E9: Electronics | F9: 1 | G9: 22111 | H9: Pune | I9: Net Banking | J9: Completed | K9: =PROPER(TRIM(H9)) -> Pune | L9: =IF(UPPER(TRIM(I8))="UPI","UPI",PROPER(TRIM(I8))) -> Net Banking | M9: =IFERROR(F9*G9,0) -> 22111 | N9: =IFERROR(VALUE(LEFT(C9,2)),"") -> 12
A10: ORD1119 | B10: CUST1198 | C10: 14-191125 | D10: Laptop | E10: Electronics | F10: 3 | G10: 15111 | H10: Mumbai | I10: Net Banking | J10: Completed | K10: =PROPER(TRIM(H10)) -> Mumbai | L10: =IF(UPPER(TRIM(I9))="UPI","UPI",PROPER(TRIM(I9))) -> Net Banking | M10: =IFERROR(F10*G10,0) -> 45333 | N10: =IFERROR(VALUE(LEFT(C10,2)),"") -> 14
A11: ORD1111 | B11: CUST1115 | C11: 11-111125 | D11: Mouse | E11: Accessories | F11: 2 | G11: 1111 | H11: Jaipur | I11: Debit Card | J11: Completed | K11: =PROPER(TRIM(H11)) -> Jaipur | L11: =IF(UPPER(TRIM(I10))="UPI","UPI",PROPER(TRIM(I10))) -> Net Banking | M11: =IFERROR(F11*G11,0) -> 2222 | N11: =IFERROR(VALUE(LEFT(C11,2)),"") -> 11
A12: ORD1111 | B12: CUST1122 | C12: 19-111125 | D12: Laptop | E12: Electronics | F12: 2 | G12: 45111 | H12: Pune | I12: Net Banking | J12: Cancelled | K12: =PROPER(TRIM(H12)) -> Pune | L12: =IF(UPPER(TRIM(I11))="UPI","UPI",PROPER(TRIM(I11))) -> Debit Card | M12: =IFERROR(F12*G12,0) -> 90222 | N12: =IFERROR(VALUE(LEFT(C12,2)),"") -> 19
A13: ORD1112 | B13: CUST1132 | C13: 13-131125 | D13: Tablet | E13: Electronics | F13: 2 | G13: 35111 | H13: Bangalore | I13: unknown | J13: Pending | K13: =PROPER(TRIM(H13)) -> Bangalore | L13: =IF(UPPER(TRIM(I12))="UPI","UPI",PROPER(TRIM(I12))) -> Net Banking | M13: =IFERROR(F13*G13,0) -> 70222 | N13: =IFERROR(VALUE(LEFT(C13,2)),"") -> 13
A14: ORD1113 | B14: CUST1143 | C14: 17-111125 | D14: Laptop | E14: Electronics | F14: 1 | G14: 52111 | H14: Delhi | I14: Net Banking | J14: Completed | K14: =PROPER(TRIM(H14)) -> Delhi | L14: =IF(UPPER(TRIM(I13))="UPI","UPI",PROPER(TRIM(I13))) -> Unknown | M14: =IFERROR(F14*G14,0) -> 52111 | N14: =IFERROR(VALUE(LEFT(C14,2)),"") -> 17
... A67: ORD1166 | B67: CUST1191 | C67: 21-111125 | D67: Smartwatch | E67: Wearables | F67: 1 | G67: 2511 | H67: Delhi | I67: unknown | J67: Completed | K67: =PROPER(TRIM(H67)) -> Delhi | L67: =IF(UPPER(TRIM(I66))="UPI","UPI",PROPER(TRIM(I66))) -> Debit Card | M67: =IFERROR(F67*G67,0) -> 2511 | N67: =IFERROR(VALUE(LEFT(C67,2)),"") -> 21
A68: ORD1167 | B68: CUST1168 | C68: 16-151125 | D68: Mouse | E68: Accessories | F68: 1 | G68: 711 | H68: Chennai | I68: Net Banking | J68: Cancelled | K68: =PROPER(TRIM(H68)) -> Chennai | L68: =IF(UPPER(TRIM(I67))="UPI","UPI",PROPER(TRIM(I67))) -> Unknown | M68: =IFERROR(F68*G68,0) -> 711 | N68: =IFERROR(VALUE(LEFT(C68,2)),"") -> 16
A69: ORD1168 | B69: CUST1161 | C69: 29-141125 | D69: Headphones | E69: Accessories | F69: 2 | G69: 3511 | H69: Pune | I69: Cash | J69: Pending | K69: =PROPER(TRIM(H69)) -> Pune | L69: =IF(UPPER(TRIM(I68))="UPI","UPI",PROPER(TRIM(I68))) -> Net Banking | M69: =IFERROR(F69*G69,0) -> 7022 | N69: =IFERROR(VALUE(LEFT(C69,2)),"") -> 29
A70: ORD1169 | B70: CUST1139 | C70: 22-181125 | D70: Laptop | E70: Electronics | F70: 4 | G70: 61111 | H70: Bangalore | I70: Cash | J70: unknown | K70: =PROPER(TRIM(H70)) -> Bangalore | L70: =IF(UPPER(TRIM(I69))="UPI","UPI",PROPER(TRIM(I69))) -> Cash | M70: =IFERROR(F70*G70,0) -> 244444 | N70: =IFERROR(VALUE(LEFT(C70,2)),"") -> 22
A71: ORD1171 | B71: CUST1173 | C71: 15-111125 | D71: Smartphone | E71: Electronics | F71: 2 | G71: 31111 | H71: Jaipur | I71: Net Banking | J71: Cancelled | K71: =PROPER(TRIM(H71)) -> Jaipur | L71: =IF(UPPER(TRIM(I70))="UPI","UPI",PROPER(TRIM(I70))) -> Cash | M71: =IFERROR(F71*G71,0) -> 62222 | N71: =IFERROR(VALUE(LEFT(C71,2)),"") -> 15
A72: ORD1171 | B72: CUST1183 | C72: 18-111125 | D72: Smartwatch | E72: Wearables | F72: 3 | G72: 2511 | H72: Jaipur | I72: Debit Card | J72: Pending | K72: =PROPER(TRIM(H72)) -> Jaipur | L72: =IF(UPPER(TRIM(I71))="UPI","UPI",PROPER(TRIM(I71))) -> Net Banking | M72: =IFERROR(F72*G72,0) -> 7533 | N72: =IFERROR(VALUE(LEFT(C72,2)),"") -> 18
A73: ORD1172 | B73: CUST1171 | C73: 19-131125 | D73: Laptop | E73: Electronics | F73: 3 | G73: 52111 | H73: Kolkata | I73: Net Banking | J73: Cancelled | K73: =PROPER(TRIM(H73)) -> Kolkata | L73: =IF(UPPER(TRIM(I72))="UPI","UPI",PROPER(TRIM(I72))) -> Debit Card | M73: =IFERROR(F73*G73,0) -> 156333 | N73: =IFERROR(VALUE(LEFT(C73,2)),"") -> 19
A74: ORD1173 | B74: CUST1197 | C74: 14-131125 | D74: Mouse | E74: Accessories | F74: 2 | G74: 711 | H74: Bangalore | I74: Cash | J74: Cancelled | K74: =PROPER(TRIM(H74)) -> Bangalore | L74: =IF(UPPER(TRIM(I73))="UPI","UPI",PROPER(TRIM(I73))) -> Net Banking | M74: =IFERROR(F74*G74,0) -> 1422 | N74: =IFERROR(VALUE(LEFT(C74,2)),"") -> 14
A75: ORD1174 | B75: CUST1149 | C75: 27-111125 | D75: Monitor | E75: Electronics | F75: 1 | G75: 22111 | H75: Kolkata | I75: UPI | J75: Cancelled | K75: =PROPER(TRIM(H75)) -> Kolkata | L75: =IF(UPPER(TRIM(I74))="UPI","UPI",PROPER(TRIM(I74))) -> Cash | M75: =IFERROR(F75*G75,0) -> 22111 | N75: =IFERROR(VALUE(LEFT(C75,2)),"") -> 27
A76: ORD1175 | B76: CUST1118 | C76: 11-131125 | D76: Keyboard | E76: Accessories | F76: 4 | G76: 1811 | H76: Jaipur | I76: UPI | J76: Pending | K76: =PROPER(TRIM(H76)) -> Jaipur | L76: =IF(UPPER(TRIM(I75))="UPI","UPI",PROPER(TRIM(I75))) -> UPI | M76: =IFERROR(F76*G76,0) -> 7244 | N76: =IFERROR(VALUE(LEFT(C76,2)),"") -> 11
A77: ORD1176 | B77: CUST1184 | C77: 11-181125 | D77: Smartwatch | E77: Wearables | F77: 0 | G77: 4111 | H77: Delhi | I77: Cash | J77: Cancelled | K77: =PROPER(TRIM(H77)) -> Delhi | L77: =IF(UPPER(TRIM(I76))="UPI","UPI",PROPER(TRIM(I76))) -> UPI | M77: =IFERROR(F77*G77,0) -> 0 | N77: =IFERROR(VALUE(LEFT(C77,2)),"") -> 11
A78: ORD1177 | B78: CUST1148 | C78: 18-121125 | D78: Tablet | E78: Electronics | F78: 3 | G78: 25111 | H78: Kolkata | I78: UPI | J78: Pending | K78: =PROPER(TRIM(H78)) -> Kolkata | L78: =IF(UPPER(TRIM(I77))="UPI","UPI",PROPER(TRIM(I77))) -> Cash | M78: =IFERROR(F78*G78,0) -> 75333 | N78: =IFERROR(VALUE(LEFT(C78,2)),"") -> 18
A79: ORD1178 | B79: CUST1117 | C79: 15-151125 | D79: Mouse | E79: Accessories | F79: 2 | G79: 411 | H79: Bangalore | I79: UPI | J79: Cancelled | K79: =PROPER(TRIM(H79)) -> Bangalore | L79: =IF(UPPER(TRIM(I78))="UPI","UPI",PROPER(TRIM(I78))) -> UPI | M79: =IFERROR(F79*G79,0) -> 822 | N79: =IFERROR(VALUE(LEFT(C79,2)),"") -> 15
A80: ORD1179 | B80: CUST1133 | C80: 14-111125 | D80: Keyboard | E80: Accessories | F80: 2 | G80: 1811 | H80: Mumbai | I80: UPI | J80: Cancelled | K80: =PROPER(TRIM(H80)) -> Mumbai | L80: =IF(UPPER(TRIM(I79))="UPI","UPI",PROPER(TRIM(I79))) -> UPI | M80: =IFERROR(F80*G80,0) -> 3622 | N80: =IFERROR(VALUE(LEFT(C80,2)),"") -> 14
... A221: ORD1221 | B221: CUST1118 | C221: 16-171125 | D221: Laptop | E221: Electronics | F221: 2 | G221: 61111 | H221: Chennai | I221: Credit Card | J221: Cancelled | K221: =PROPER(TRIM(H221)) -> Chennai | L221: =IF(UPPER(TRIM(I220))="UPI","UPI",PROPER(TRIM(I220))) -> Cash | M221: =IFERROR(F221*G221,0) -> 122222 | N221: =IFERROR(VALUE(LEFT(C221,2)),"") -> 16
A222: ORD1221 | B222: CUST1124 | C222: 19-151125 | D222: Keyboard | E222: Accessories | F222: 1 | G222: 1811 | H222: Jaipur | I222: Debit Card | J222: Cancelled | K222: =PROPER(TRIM(H222)) -> Jaipur | L222: =IF(UPPER(TRIM(I221))="UPI","UPI",PROPER(TRIM(I221))) -> Credit Card | M222: =IFERROR(F222*G222,0) -> 1811 | N222: =IFERROR(VALUE(LEFT(C222,2)),"") -> 19
A223: ORD1222 | B223: CUST1185 | C223: 17-151125 | D223: Keyboard | E223: Accessories | F223: 1 | G223: 1811 | H223: Bangalore | I223: Debit Card | J223: Cancelled | K223: =PROPER(TRIM(H223)) -> Bangalore | L223: =IF(UPPER(TRIM(I222))="UPI","UPI",PROPER(TRIM(I222))) -> Debit Card | M223: =IFERROR(F223*G223,0) -> 1811 | N223: =IFERROR(VALUE(LEFT(C223,2)),"") -> 17
A224: ORD1223 | B224: CUST1191 | C224: 27-121125 | D224: Laptop | E224: Electronics | F224: 2 | G224: 68111 | H224: Kolkata | I224: Net Banking | J224: Cancelled | K224: =PROPER(TRIM(H224)) -> Kolkata | L224: =IF(UPPER(TRIM(I223))="UPI","UPI",PROPER(TRIM(I223))) -> Debit Card | M224: =IFERROR(F224*G224,0) -> 136222 | N224: =IFERROR(VALUE(LEFT(C224,2)),"") -> 27
A225: ORD1224 | B225: CUST1129 | C225: 15-111125 | D225: Headphones | E225: Accessories | F225: 2 | G225: 1811 | H225: Jaipur | I225: Net Banking | J225: Pending | K225: =PROPER(TRIM(H225)) -> Jaipur | L225: =IF(UPPER(TRIM(I224))="UPI","UPI",PROPER(TRIM(I224))) -> Net Banking | M225: =IFERROR(F225*G225,0) -> 3622 | N225: =IFERROR(VALUE(LEFT(C225,2)),"") -> 15
A226: ORD1225 | B226: CUST1176 | C226: 17-131125 | D226: Laptop | E226: Electronics | F226: 3 | G226: 52111 | H226: Mumbai | I226: UPI | J226: Cancelled | K226: =PROPER(TRIM(H226)) -> Mumbai | L226: =IF(UPPER(TRIM(I225))="UPI","UPI",PROPER(TRIM(I225))) -> Net Banking | M226: =IFERROR(F226*G226,0) -> 156333 | N226: =IFERROR(VALUE(LEFT(C226,2)),"") -> 17
A227: ORD1226 | B227: CUST1182 | C227: 12-181125 | D227: Monitor | E227: Electronics | F227: 1 | G227: 16111 | H227: Hyderabad | I227: Debit Card | J227: Completed | K227: =PROPER(TRIM(H227)) -> Hyderabad | L227: =IF(UPPER(TRIM(I226))="UPI","UPI",PROPER(TRIM(I226))) -> UPI | M227: =IFERROR(F227*G227,0) -> 16111 | N227: =IFERROR(VALUE(LEFT(C227,2)),"") -> 12
A228: ORD1227 | B228: CUST1191 | C228: 11-111125 | D228: Monitor | E228: Electronics | F228: 2 | G228: 16111 | H228: Chennai | I228: Net Banking | J228: Completed | K228: =PROPER(TRIM(H228)) -> Chennai | L228: =IF(UPPER(TRIM(I227))="UPI","UPI",PROPER(TRIM(I227))) -> Debit Card | M228: =IFERROR(F228*G228,0) -> 32222 | N228: =IFERROR(VALUE(LEFT(C228,2)),"") -> 11
A229: ORD1228 | B229: CUST1122 | C229: 13-161125 | D229: Headphones | E229: Accessories | F229: 3 | G229: 3511 | H229: Delhi | I229: Debit Card | J229: Pending | K229: =PROPER(TRIM(H229)) -> Delhi | L229: =IF(UPPER(TRIM(I228))="UPI","UPI",PROPER(TRIM(I228))) -> Net Banking | M229: =IFERROR(F229*G229,0) -> 10533 | N229: =IFERROR(VALUE(LEFT(C229,2)),"") -> 13
A230: ORD1229 | B230: CUST1157 | C230: 17-171125 | D230: Laptop | E230: Electronics | F230: 3 | G230: 52111 | H230: Chennai | I230: Credit Card | J230: Pending | K230: =PROPER(TRIM(H230)) -> Chennai | L230: =IF(UPPER(TRIM(I229))="UPI","UPI",PROPER(TRIM(I229))) -> Debit Card | M230: =IFERROR(F230*G230,0) -> 156333 | N230: =IFERROR(VALUE(LEFT(C230,2)),"") -> 17
A231: ORD1231 | B231: CUST1115 | C231: 17-121125 | D231: Smartwatch | E231: Wearables | F231: 4 | G231: 9111 | H231: Pune | I231: UPI | J231: Pending | K231: =PROPER(TRIM(H231)) -> Pune | L231: =IF(UPPER(TRIM(I230))="UPI","UPI",PROPER(TRIM(I230))) -> Credit Card | M231: =IFERROR(F231*G231,0) -> 36444 | N231: =IFERROR(VALUE(LEFT(C231,2)),"") -> 17
A232: ORD1231 | B232: CUST1179 | C232: 11-111125 | D232: Mouse | E232: Accessories | F232: 1 | G232: 411 | H232: Hyderabad | I232: UPI | J232: Pending | K232: =PROPER(TRIM(H232)) -> Hyderabad | L232: =IF(UPPER(TRIM(I231))="UPI","UPI",PROPER(TRIM(I231))) -> UPI | M232: =IFERROR(F232*G232,0) -> 411 | N232: =IFERROR(VALUE(LEFT(C232,2)),"") -> 11
...
